Exception happened during processing of request from ('127.0.0.1', 60010)
Traceback (most recent call last):
  File "/usr/lib/python3.6/socketserver.py", line 317, in _handle_request_noblock
    self.process_request(request, client_address)
  File "/usr/lib/python3.6/socketserver.py", line 666, in process_request
    t.start()
  File "/usr/lib/python3.6/threading.py", line 846, in start
    _start_new_thread(self._bootstrap, ())
RuntimeError: can't start new thread













Exception in thread Thread-4:
Traceback (most recent call last):
  File "/usr/lib/python3.6/threading.py", line 916, in _bootstrap_inner
    self.run()
  File "/usr/lib/python3.6/threading.py", line 864, in run
    self._target(*self._args, **self._kwargs)
  File "/usr/lib/python3.6/multiprocessing/managers.py", line 177, in accepter
    t.start()
  File "/usr/lib/python3.6/threading.py", line 846, in start
    _start_new_thread(self._bootstrap, ())
RuntimeError: can't start new thread

Process Process-612:
Traceback (most recent call last):
  File "/usr/lib/python3/dist-packages/urllib3/connectionpool.py", line 601, in urlopen
    chunked=chunked)
  File "/usr/lib/python3/dist-packages/urllib3/connectionpool.py", line 387, in _make_request
    six.raise_from(e, None)
  File "<string>", line 3, in raise_from
  File "/usr/lib/python3/dist-packages/urllib3/connectionpool.py", line 383, in _make_request
    httplib_response = conn.getresponse()
  File "/usr/lib/python3.6/http/client.py", line 1331, in getresponse
    response.begin()
  File "/usr/lib/python3.6/http/client.py", line 297, in begin
    version, status, reason = self._read_status()
  File "/usr/lib/python3.6/http/client.py", line 266, in _read_status
    raise RemoteDisconnected("Remote end closed connection without"
http.client.RemoteDisconnected: Remote end closed connection without response

During handling of the above exception, another exception occurred:

Traceback (most recent call last):
  File "/usr/lib/python3/dist-packages/requests/adapters.py", line 440, in send
    timeout=timeout
  File "/usr/lib/python3/dist-packages/urllib3/connectionpool.py", line 639, in urlopen
    _stacktrace=sys.exc_info()[2])
  File "/usr/lib/python3/dist-packages/urllib3/util/retry.py", line 357, in increment
    raise six.reraise(type(error), error, _stacktrace)
  File "/usr/lib/python3/dist-packages/six.py", line 692, in reraise
    raise value.with_traceback(tb)
  File "/usr/lib/python3/dist-packages/urllib3/connectionpool.py", line 601, in urlopen
    chunked=chunked)
  File "/usr/lib/python3/dist-packages/urllib3/connectionpool.py", line 387, in _make_request
    six.raise_from(e, None)
  File "<string>", line 3, in raise_from
  File "/usr/lib/python3/dist-packages/urllib3/connectionpool.py", line 383, in _make_request
    httplib_response = conn.getresponse()
  File "/usr/lib/python3.6/http/client.py", line 1331, in getresponse
    response.begin()
  File "/usr/lib/python3.6/http/client.py", line 297, in begin
    version, status, reason = self._read_status()
  File "/usr/lib/python3.6/http/client.py", line 266, in _read_status
    raise RemoteDisconnected("Remote end closed connection without"
urllib3.exceptions.ProtocolError: ('Connection aborted.', RemoteDisconnected('Remote end closed connection without response',))

During handling of the above exception, another exception occurred:

Traceback (most recent call last):
  File "/usr/lib/python3.6/multiprocessing/process.py", line 258, in _bootstrap
    self.run()
  File "/usr/lib/python3.6/multiprocessing/process.py", line 93, in run
    self._target(*self._args, **self._kwargs)
  File "train_parallel.py", line 29, in simulate
    sim.do_step(step)
  File "/home/mimmo/Desktop/TLCS Parallel/simulators/simulator_gru.py", line 329, in do_step
    self.action = requests.post('http://127.0.0.1:5000/act', json={'states': self.states.tolist()}).json()['action']
  File "/usr/lib/python3/dist-packages/requests/api.py", line 112, in post
    return request('post', url, data=data, json=json, **kwargs)
  File "/usr/lib/python3/dist-packages/requests/api.py", line 58, in request
    return session.request(method=method, url=url, **kwargs)
  File "/usr/lib/python3/dist-packages/requests/sessions.py", line 520, in request
    resp = self.send(prep, **send_kwargs)
  File "/usr/lib/python3/dist-packages/requests/sessions.py", line 630, in send
    r = adapter.send(request, **kwargs)
  File "/usr/lib/python3/dist-packages/requests/adapters.py", line 490, in send
    raise ConnectionError(err, request=request)
requests.exceptions.ConnectionError: ('Connection aborted.', RemoteDisconnected('Remote end closed connection without response',))
Error: tcpip::Socket::recvAndCheck @ recv: peer shutdown
Quitting (on error).
